<?xml version="1.0"?>
<robot name="body__32__">
    <link name="body__32__">
        <inertial>
            <origin rpy="-3.141593 3.141593 -3.141593" xyz="0.000000 0.000000 0.000000" />
            <inertia ixx="1.858" iyy="1.052" izz="1.858" ixy="0.0" ixz="0.0" iyz="0.0" />
            <mass value="6.278" />
        </inertial>
        <collision>
            <origin rpy="-3.141593 3.141593 -3.141593" xyz="0.000000 0.000000 0.000000" />
            <geometry>
                <box size="0.100000 0.200000 0.500000" />
            </geometry>
        </collision>
    </link>
    <link name="Wheel1__34__">
        <inertial>
            <origin rpy="-3.141593 3.141593 -3.141593" xyz="0.000000 -0.000000 0.000000" />
            <inertia ixx="0.001" iyy="0.001" izz="0.001" ixy="0.0" ixz="0.0" iyz="0.0" />
            <mass value="1.516" />
        </inertial>
        <collision>
            <origin rpy="-3.141593 3.141593 -3.141593" xyz="0.000000 0.000000 0.000000" />
            <geometry>
                 <cylinder length="0.05" radius="0.0846" />
            </geometry>
        </collision>
    </link>
    <joint name="Revolute_joint1__33__" type="continuous">
        <axis xyz="0 0 1" />
        <parent link="body__32__" />
        <child link="Wheel1__34__" />
        <origin rpy="-1.570770 3.141593 -3.141593" xyz="0.000000 -0.180000 -0.250000" />
        <limit effort="100000000.0" velocity="100"/>
        <dynamics damping="0.1" friction="0.25"/>
    </joint>
    <link name="Wheel2__36__">
        <inertial>
            <origin rpy="-3.141593 3.141593 -3.141593" xyz="0.000000 -0.000000 0.000000" />
            <inertia ixx="0.001" iyy="0.001" izz="0.001" ixy="0.0" ixz="0.0" iyz="0.0" />
            <mass value="1.516" />
        </inertial>
        <collision>
            <origin rpy="-3.141593 3.141593 -3.141593" xyz="0.000000 0.000000 0.000000" />
            <geometry>
                 <cylinder length="0.05" radius="0.0846" />
            </geometry>
        </collision>
    </link>
    <joint name="Revolute_joint2__35__" type="continuous">
        <axis xyz="0 0 1" />
        <parent link="body__32__" />
        <child link="Wheel2__36__" />
        <origin rpy="-1.570771 3.141593 3.141593" xyz="0.000000 0.180000 -0.250000" />
        <limit effort="100000000.0" velocity="100"/>
        <dynamics damping="0.1" friction="0.25"/>
    </joint>
</robot>